<?xml version="1.0" ?>
<!-- =================================================================================== -->
<!-- |    This document was autogenerated by xacro from model.xacro                    | -->
<!-- |    EDITING THIS FILE BY HAND IS NOT RECOMMENDED                                 | -->
<!-- =================================================================================== -->
<!-- Revolute-Revolute Manipulator -->
<robot name="rrbot">
  <topic_name>/lf</topic_name>
  <frame_name>linefollower</frame_name>
  <!-- Beams are square in length and width -->
  <!-- Beams are square in length and width -->
  <!-- Beams are square in length and width -->
  <!-- WHEELS -->
  <link name="cas_wheel">
    <inertial>
      <origin rpy="1.55 0.0 0.0" xyz="0 0 0.0005"/>
      <mass value="10"/>
      <inertia ixx="1.0" ixy="0.0" ixz="0.0" iyy="1.0" iyz="0.0" izz="1.0"/>
    </inertial>
    <visual>
      <origin rpy="1.55 0.0 0.0" xyz="0 0 0 "/>
      <geometry>
        <sphere radius="0.005"/>
      </geometry>
      <material name="">
        <color rgba="1.0 0.0 0.0 1.0"/>
        <texture filename=""/>
      </material>
    </visual>
    <collision>
      <origin rpy="1.55 0.0 0.0" xyz="0 0 0 "/>
      <geometry>
        <sphere radius="0.005"/>
      </geometry>
    </collision>
  </link>
  <link name="wheel">
    <inertial>
      <origin rpy="1.55 0.0 0.0" xyz="0 0 0.0005"/>
      <mass value="30"/>
      <inertia ixx="1.0" ixy="0.0" ixz="0.0" iyy="1.0" iyz="0.0" izz="1.0"/>
    </inertial>
    <visual>
      <origin rpy="1.55 0.0 0.0" xyz="0 0 0 "/>
      <geometry>
        <cylinder length="0.008" radius="0.012"/>
      </geometry>
      <material name="">
        <color rgba="1.0 0.0 0.0 1.0"/>
        <texture filename=""/>
      </material>
    </visual>
    <collision>
      <origin rpy="1.55 0.0 0.0" xyz="0 0 0 "/>
      <geometry>
        <cylinder length="0.008" radius="0.012"/>
      </geometry>
    </collision>
  </link>
  <link name="wheel2">
    <inertial>
      <origin rpy="1.55 0.0 0.0" xyz="0 0 0.0005"/>
      <mass value="30"/>
      <inertia ixx="1.0" ixy="0.0" ixz="0.0" iyy="1.0" iyz="0.0" izz="1.0"/>
    </inertial>
    <visual>
      <origin rpy="1.55 0.0 0.0" xyz="0 0 0 "/>
      <geometry>
        <cylinder length="0.008" radius="0.012"/>
      </geometry>
      <material name="">
        <color rgba="1.0 0.0 0.0 1.0"/>
        <texture filename=""/>
      </material>
    </visual>
    <collision>
      <origin rpy="1.55 0.0 0.0" xyz="0 0 0 "/>
      <geometry>
        <cylinder length="0.008" radius="0.012"/>
      </geometry>
    </collision>
  </link>
  <!-- Chassis front -->
  <link name="chassis_front">
    <visual>
      <origin rpy="0 0 0" xyz="0 0 0.0005"/>
      <geometry>
        <box size="0.01 0.04 0.001"/>
      </geometry>
    </visual>
    <collision>
      <origin rpy="0 0 0" xyz="0 0 0.0005"/>
      <geometry>
        <box size="0.01 0.04 0.001"/>
      </geometry>
    </collision>
    <inertial>
      <origin rpy="0 0 0" xyz="0 0 0.0005"/>
      <mass value="0.1"/>
      <inertia ixx="1.0" ixy="0.0" ixz="0.0" iyy="1.0" iyz="0.0" izz="1.0"/>
    </inertial>
  </link>
  <!-- Chassis mid -->
  <link name="chassis_mid">
    <visual>
      <origin rpy="0 0 0" xyz="0 0 0.0005"/>
      <geometry>
        <box size="0.03 0.01 0.001"/>
      </geometry>
    </visual>
    <collision>
      <origin rpy="0 0 0" xyz="0 0 0.0005"/>
      <geometry>
        <box size="0.03 0.01 0.001"/>
      </geometry>
    </collision>
    <inertial>
      <origin rpy="0 0 0" xyz="0 0 0.0005"/>
      <mass value="0.3"/>
      <inertia ixx="1.0" ixy="0.0" ixz="0.0" iyy="1.0" iyz="0.0" izz="1.0"/>
    </inertial>
  </link>
  <!-- Chassis back -->
  <link name="chassis_back">
    <visual>
      <origin rpy="0 0 0" xyz="0 0 0.0005"/>
      <geometry>
        <box size="0.025 0.04 0.001"/>
      </geometry>
    </visual>
    <collision>
      <origin rpy="0 0 0" xyz="0 0 0.0005"/>
      <geometry>
        <box size="0.025 0.04 0.001"/>
      </geometry>
    </collision>
    <inertial>
      <origin rpy="0 0 0" xyz="0 0 0.0005"/>
      <mass value="2"/>
      <inertia ixx="1.0" ixy="0.0" ixz="0.0" iyy="1.0" iyz="0.0" izz="1.0"/>
    </inertial>
  </link>
  <!-- Joint between both chassises -->
  <joint name="joint_back_mid" type="fixed">
    <parent link="chassis_back"/>
    <child link="chassis_mid"/>
    <origin rpy="0 0 0" xyz="0.0275 0 0"/>
  </joint>
  <!-- Joint between both chassises -->
  <joint name="joint_mid_front" type="fixed">
    <parent link="chassis_mid"/>
    <child link="chassis_front"/>
    <origin rpy="0 0 0" xyz="0.02 0 0"/>
  </joint>
  <!-- Joint between chassis back and wheel -->
  <joint name="joint_left_wheel_back" type="continuous">
    <parent link="chassis_back"/>
    <child link="wheel"/>
    <limit effort="0.0" lower="0.0" upper="0.0" velocity="0.0"/>
    <origin rpy="0 0 0" xyz="0 0.024 0"/>
    <axis rpy="0 0 0" xyz="0 1 0"/>
  </joint>
  <!-- Joint between chassis back and wheel -->
  <joint name="joint_right_wheel_back" type="continuous">
    <parent link="chassis_back"/>
    <child link="wheel2"/>
    <limit effort="0.0" lower="0.0" upper="0.0" velocity="0.0"/>
    <origin rpy="0 0 0" xyz="0 -0.024 0"/>
    <axis rpy="0 0 0" xyz="0 1 0"/>
  </joint>
  <!-- Joint between chassis back and wheel -->
  <joint name="joint_cas_wheel_mid" type="continuous">
    <parent link="chassis_mid"/>
    <child link="cas_wheel"/>
    <limit effort="0.0" lower="0.0" upper="0.0" velocity="0.0"/>
    <origin rpy="0 0 0" xyz="0 0 -0.005"/>
    <axis rpy="0 0 0" xyz="0 1 0"/>
  </joint>
  <gazebo>
    <plugin filename="libgazebo_ros_p3d.so" name="control_p3d">
      <always_on>true</always_on>
      <body_name>chassis_back</body_name>
      <topic_name>odom</topic_name>
      <frame_name>map</frame_name>
      <update_rate>50</update_rate>
    </plugin>
    <plugin filename="libgazebo_ros_diff_drive.so" name="diff_drive">
      <ros>
        <namespace>/lf</namespace>
        <remapping>cmd_lf:=cmd_lf</remapping>
        <remapping>odom:=odom_lf</remapping>
      </ros>
      <!-- wheels -->
      <left_joint>left_wheel_joint</left_joint>
      <right_joint>right_wheel_joint</right_joint>
      <!-- kinematics -->
      <wheel_separation>1.25</wheel_separation>
      <wheel_diameter>0.6</wheel_diameter>
      <!-- limits -->
      <max_wheel_torque>20</max_wheel_torque>
      <max_wheel_acceleration>1.0</max_wheel_acceleration>
      <!-- output -->
      <publish_odom>true</publish_odom>
      <publish_odom_tf>true</publish_odom_tf>
      <publish_wheel_tf>true</publish_wheel_tf>
      <odom_publish>true</odom_publish>
      <odometry_frame>map</odometry_frame>
      <odom_frame_id>odom</odom_frame_id>
      <robot_base_frame>chassis_back</robot_base_frame>
      <always_on>true</always_on>
    </plugin>
  </gazebo>
</robot>
