<?xml version="1.0" ?>
<!-- =================================================================================== -->
<!-- |    This document was autogenerated by xacro from model.xacro                    | -->
<!-- |    EDITING THIS FILE BY HAND IS NOT RECOMMENDED                                 | -->
<!-- =================================================================================== -->
<!-- Revolute-Revolute Manipulator -->
<robot name="rrbot">
  <!-- Beams are square in length and width -->
  <!-- Beams are square in length and width -->
  <!-- WHEELS -->
  <link name="cas_wheel">
    <inertial>
      <origin rpy="1.55 0.0 0.0" xyz="0 0 0.0025"/>
      <mass value="1"/>
      <inertia ixx="1.0" ixy="0.0" ixz="0.0" iyy="1.0" iyz="0.0" izz="1.0"/>
    </inertial>
    <visual>
      <origin rpy="1.55 0.0 0.0" xyz="0 0 0 "/>
      <geometry>
        <sphere radius="0.012"/>
      </geometry>
      <material name="">
        <color rgba="1.0 0.0 0.0 1.0"/>
        <texture filename=""/>
      </material>
    </visual>
    <collision>
      <origin rpy="1.55 0.0 0.0" xyz="0 0 0 "/>
      <geometry>
        <sphere radius="0.012"/>
      </geometry>
    </collision>
  </link>
  <link name="wheel">
    <inertial>
      <origin rpy="1.55 0.0 0.0" xyz="0 0 0.0025"/>
      <mass value="1"/>
      <inertia ixx="1.0" ixy="0.0" ixz="0.0" iyy="1.0" iyz="0.0" izz="1.0"/>
    </inertial>
    <visual>
      <origin rpy="1.55 0.0 0.0" xyz="0 0 0 "/>
      <geometry>
        <cylinder length="0.015" radius="0.012"/>
      </geometry>
      <material name="">
        <color rgba="1.0 0.0 0.0 1.0"/>
        <texture filename=""/>
      </material>
    </visual>
    <collision>
      <origin rpy="1.55 0.0 0.0" xyz="0 0 0 "/>
      <geometry>
        <cylinder length="0.015" radius="0.012"/>
      </geometry>
    </collision>
  </link>
  <link name="wheel2">
    <inertial>
      <origin rpy="1.55 0.0 0.0" xyz="0 0 0.0025"/>
      <mass value="1"/>
      <inertia ixx="1.0" ixy="0.0" ixz="0.0" iyy="1.0" iyz="0.0" izz="1.0"/>
    </inertial>
    <visual>
      <origin rpy="1.55 0.0 0.0" xyz="0 0 0 "/>
      <geometry>
        <cylinder length="0.015" radius="0.012"/>
      </geometry>
      <material name="">
        <color rgba="1.0 0.0 0.0 1.0"/>
        <texture filename=""/>
      </material>
    </visual>
    <collision>
      <origin rpy="1.55 0.0 0.0" xyz="0 0 0 "/>
      <geometry>
        <cylinder length="0.015" radius="0.012"/>
      </geometry>
    </collision>
  </link>
  <!-- Chassis front -->
  <link name="chassis_front">
    <visual>
      <origin rpy="0 0 0" xyz="0 0 0.0025"/>
      <geometry>
        <box size="0.06 0.016 0.005"/>
      </geometry>
    </visual>
    <collision>
      <origin rpy="0 0 0" xyz="0 0 0.0025"/>
      <geometry>
        <box size="0.06 0.016 0.005"/>
      </geometry>
    </collision>
    <inertial>
      <origin rpy="0 0 0" xyz="0 0 0.0025"/>
      <mass value="1"/>
      <inertia ixx="1.0" ixy="0.0" ixz="0.0" iyy="1.0" iyz="0.0" izz="1.0"/>
    </inertial>
  </link>
  <!-- Chassis back -->
  <link name="chassis_back">
    <visual>
      <origin rpy="0 0 0" xyz="0 0 0.0025"/>
      <geometry>
        <box size="0.025 0.05 0.005"/>
      </geometry>
    </visual>
    <collision>
      <origin rpy="0 0 0" xyz="0 0 0.0025"/>
      <geometry>
        <box size="0.025 0.05 0.005"/>
      </geometry>
    </collision>
    <inertial>
      <origin rpy="0 0 0" xyz="0 0 0.0025"/>
      <mass value="1"/>
      <inertia ixx="1.0" ixy="0.0" ixz="0.0" iyy="1.0" iyz="0.0" izz="1.0"/>
    </inertial>
  </link>
  <!-- Joint between both chassises -->
  <joint name="joint_front_back" type="fixed">
    <parent link="chassis_back"/>
    <child link="chassis_front"/>
    <origin rpy="0 0 0" xyz="0.042499999999999996 0 0"/>
  </joint>
  <!-- Joint between chassis back and wheel -->
  <joint name="joint_left_wheel_back" type="continuous">
    <parent link="chassis_back"/>
    <child link="wheel"/>
    <limit effort="0.0" lower="0.0" upper="0.0" velocity="0.0"/>
    <origin rpy="0 0 0" xyz="0 0.0325 0"/>
    <axis rpy="0 0 0" xyz="0 1 0"/>
  </joint>
  <!-- Joint between chassis back and wheel -->
  <joint name="joint_right_wheel_back" type="continuous">
    <parent link="chassis_back"/>
    <child link="wheel2"/>
    <limit effort="0.0" lower="0.0" upper="0.0" velocity="0.0"/>
    <origin rpy="0 0 0" xyz="0 -0.0325 0"/>
    <axis rpy="0 0 0" xyz="0 1 0"/>
  </joint>
</robot>
