<sdf version='1.7'>
  <model name='rrbot'>
    <link name='chassis_back'>
      <inertial>
        <pose>0.005417 0 0.0005 0 -0 0</pose>
        <mass>2.4</mass>
        <inertia>
          <ixx>3</ixx>
          <ixy>0</ixy>
          <ixz>8.47033e-22</ixz>
          <iyy>3.00038</iyy>
          <iyz>0</iyz>
          <izz>3.00038</izz>
        </inertia>
      </inertial>
      <collision name='chassis_back_collision'>
        <pose>0 0 0.0005 0 -0 0</pose>
        <geometry>
          <box>
            <size>0.025 0.04 0.001</size>
          </box>
        </geometry>
      </collision>
      <collision name='chassis_back_fixed_joint_lump__chassis_mid_collision_1'>
        <pose>0.0275 0 0.0005 0 -0 0</pose>
        <geometry>
          <box>
            <size>0.03 0.01 0.001</size>
          </box>
        </geometry>
      </collision>
      <collision name='chassis_back_fixed_joint_lump__chassis_front_collision_2'>
        <pose>0.0475 0 0.0005 0 -0 0</pose>
        <geometry>
          <box>
            <size>0.01 0.04 0.001</size>
          </box>
        </geometry>
      </collision>
      <visual name='chassis_back_visual'>
        <pose>0 0 0.0005 0 -0 0</pose>
        <geometry>
          <box>
            <size>0.025 0.04 0.001</size>
          </box>
        </geometry>
      </visual>
      <visual name='chassis_back_fixed_joint_lump__chassis_mid_visual_1'>
        <pose>0.0275 0 0.0005 0 -0 0</pose>
        <geometry>
          <box>
            <size>0.03 0.01 0.001</size>
          </box>
        </geometry>
      </visual>
      <visual name='chassis_back_fixed_joint_lump__chassis_front_visual_2'>
        <pose>0.0475 0 0.0005 0 -0 0</pose>
        <geometry>
          <box>
            <size>0.01 0.04 0.001</size>
          </box>
        </geometry>
      </visual>
    </link>
    <joint name='joint_cas_wheel_mid' type='revolute'>
      <pose relative_to='chassis_back'>0.0275 0 -0.005 0 -0 0</pose>
      <parent>chassis_back</parent>
      <child>cas_wheel</child>
      <axis>
        <xyz>0 1 0</xyz>
        <limit>
          <lower>-1e+16</lower>
          <upper>1e+16</upper>
        </limit>
        <dynamics>
          <spring_reference>0</spring_reference>
          <spring_stiffness>0</spring_stiffness>
        </dynamics>
      </axis>
    </joint>
    <link name='cas_wheel'>
      <pose relative_to='joint_cas_wheel_mid'>0 0 0 0 -0 0</pose>
      <inertial>
        <pose>0 0 0.0005 1.55 -0 0</pose>
        <mass>3</mass>
        <inertia>
          <ixx>1</ixx>
          <ixy>0</ixy>
          <ixz>0</ixz>
          <iyy>1</iyy>
          <iyz>0</iyz>
          <izz>1</izz>
        </inertia>
      </inertial>
      <collision name='cas_wheel_collision'>
        <pose>0 0 0 1.55 -0 0</pose>
        <geometry>
          <sphere>
            <radius>0.005</radius>
          </sphere>
        </geometry>
      </collision>
      <visual name='cas_wheel_visual'>
        <pose>0 0 0 1.55 -0 0</pose>
        <geometry>
          <sphere>
            <radius>0.005</radius>
          </sphere>
        </geometry>
      </visual>
    </link>
    <joint name='joint_left_wheel_back' type='revolute'>
      <pose relative_to='chassis_back'>0 0.024 0 0 -0 0</pose>
      <parent>chassis_back</parent>
      <child>wheel</child>
      <axis>
        <xyz>0 1 0</xyz>
        <limit>
          <lower>-1e+16</lower>
          <upper>1e+16</upper>
        </limit>
        <dynamics>
          <spring_reference>0</spring_reference>
          <spring_stiffness>0</spring_stiffness>
        </dynamics>
      </axis>
    </joint>
    <link name='wheel'>
      <pose relative_to='joint_left_wheel_back'>0 0 0 0 -0 0</pose>
      <inertial>
        <pose>0 0 0.0005 1.55 -0 0</pose>
        <mass>3</mass>
        <inertia>
          <ixx>1</ixx>
          <ixy>0</ixy>
          <ixz>0</ixz>
          <iyy>1</iyy>
          <iyz>0</iyz>
          <izz>1</izz>
        </inertia>
      </inertial>
      <collision name='wheel_collision'>
        <pose>0 0 0 1.55 -0 0</pose>
        <geometry>
          <cylinder>
            <length>0.008</length>
            <radius>0.012</radius>
          </cylinder>
        </geometry>
      </collision>
      <visual name='wheel_visual'>
        <pose>0 0 0 1.55 -0 0</pose>
        <geometry>
          <cylinder>
            <length>0.008</length>
            <radius>0.012</radius>
          </cylinder>
        </geometry>
      </visual>
    </link>
    <joint name='joint_right_wheel_back' type='revolute'>
      <pose relative_to='chassis_back'>0 -0.024 0 0 -0 0</pose>
      <parent>chassis_back</parent>
      <child>wheel2</child>
      <axis>
        <xyz>0 1 0</xyz>
        <limit>
          <lower>-1e+16</lower>
          <upper>1e+16</upper>
        </limit>
        <dynamics>
          <spring_reference>0</spring_reference>
          <spring_stiffness>0</spring_stiffness>
        </dynamics>
      </axis>
    </joint>
    <link name='wheel2'>
      <pose relative_to='joint_right_wheel_back'>0 0 0 0 -0 0</pose>
      <inertial>
        <pose>0 0 0.0005 1.55 -0 0</pose>
        <mass>3</mass>
        <inertia>
          <ixx>1</ixx>
          <ixy>0</ixy>
          <ixz>0</ixz>
          <iyy>1</iyy>
          <iyz>0</iyz>
          <izz>1</izz>
        </inertia>
      </inertial>
      <collision name='wheel2_collision'>
        <pose>0 0 0 1.55 -0 0</pose>
        <geometry>
          <cylinder>
            <length>0.008</length>
            <radius>0.012</radius>
          </cylinder>
        </geometry>
      </collision>
      <visual name='wheel2_visual'>
        <pose>0 0 0 1.55 -0 0</pose>
        <geometry>
          <cylinder>
            <length>0.008</length>
            <radius>0.012</radius>
          </cylinder>
        </geometry>
      </visual>
    </link>
  </model>
</sdf>
